Workbook
Name NativeTimeline_Date: #N/A
Name NativeTimeline_Date1: #N/A
Name Slicer_Date: #N/A
Name Slicer_Years: #N/A

Sheet Park vs Hotel_Summary
T30: Area | U30: =U46 -> Previous year daily usage (kWh) [Park OPEN] | V30: =U48 -> Current year daily usage (kWh) [Park OPEN] | W30: Difference in %
T31: Date | U31: =Daily_Pivot!$A$4 -> 45944 | V31: =Daily_Pivot!$A$5 -> 46309
T32: Park power consumption | U32: =Daily_Pivot!$B$4 -> 148128.63 | V32: =Daily_Pivot!$B$5 -> 148729.41 | W32: =(V32-U32)/U32 -> 0.0040557676 | X32: =(V32-U32)/U32 -> 0.0040557676
T33: Hotel power consumption | U33: =Daily_Pivot!$C$4 -> 68731.23 | V33: =Daily_Pivot!$C$5 -> 59184.499 | W33: =(V33-U33)/U33 -> -0.13889946 | X33: =(V33-U33)/U33 -> -0.13889946
T34: CCP power consumption | U34: =Daily_Pivot!$D$4 -> 93862.874 | V34: =Daily_Pivot!$D$5 -> 65207.915 | W34: =(V34-U34)/U34 -> -0.30528534 | X34: =(V34-U34)/U34 -> -0.30528534
T35: HCCP power consumption | U35: =Daily_Pivot!$E$4 -> 12557.227 | V35: =Daily_Pivot!$E$5 -> 16804.44 | W35: =(V35-U35)/U35 -> 0.33822852 | X35: =(V35-U35)/U35 -> 0.33822852
T36: Total | U36: =SUM(U32:U35) -> 323279.97 | V36: =SUM(V32:V35) -> 289926.26 | W36: =(V36-U36)/U36 -> -0.10317281 | X36: =(V36-U36)/U36 -> -0.10317281
T38: Area | U38: Previous monthly usage (kWh) | V38: Current monthly usage (kWh) | W38: Difference in %
T39: Month | U39: ='Park vs Hotel_Pivot'!$A$5&"-"&'Park vs Hotel_Pivot'!$A$4 -> Oct-2025 | V39: ='Park vs Hotel_Pivot'!$A$7&"-"&'Park vs Hotel_Pivot'!$A$6 -> Oct-2026
T40: Park + CCP | U40: ='Park vs Hotel_Pivot'!$B$5 -> 6770571.2 | V40: ='Park vs Hotel_Pivot'!$B$7 -> 2957539.1 | W40: =(V40-U40)/U40 -> -0.56317731 | X40: =(V40-U40)/U40 -> -0.56317731
T41: Hotel + HCCP | U41: ='Park vs Hotel_Pivot'!$C$5 -> 2482871.8 | V41: ='Park vs Hotel_Pivot'!$C$7 -> 1157489.2 | W41: =(V41-U41)/U41 -> -0.53381032 | X41: =(V41-U41)/U41 -> -0.53381032
T42: Total | U42: =SUBTOTAL(109,U39:U41) -> 9253443.1 | V42: =SUBTOTAL(109,V39:V41) -> 4115028.3 | W42: =(V42-U42)/U42 -> -0.5552976 | X42: =(V42-U42)/U42 -> -0.5552976
T44: Row Labels
T45: 45944
T46: OPEN | U46: ="Previous year daily usage (kWh) [Park"&" "&T46&"]" -> Previous year daily usage (kWh) [Park OPEN]
T47: 46309
T48: OPEN | U48: ="Current year daily usage (kWh) [Park"&" "&T48&"]" -> Current year daily usage (kWh) [Park OPEN]
T49: Grand Total
W994: 24.2
W1180: 28.8 | X1180: 0 | Y1180: Park Close

Sheet Park&Hotel_Pivot
A1: 30 Days | B1: TRUE
A3: Row Labels | B3: Theme Park | C3: Hotel
A4: 46280 | B4: 147822.75 | C4: 65833.221
A5: 46281 | B5: 146772.98 | C5: 52962.604
A6: 46282 | B6: 145128.93 | C6: 41347.818
A7: 46283 | B7: 146526.86 | C7: 41836.17
A8: 46284 | B8: 148751.36 | C8: 55345.069
A9: 46285 | B9: 147068.38 | C9: 69317.855
A10: 46286 | B10: 146979.51 | C10: 68313.619
A11: 46287 | B11: 145054.17 | C11: 68824.084
A12: 46288 | B12: 146562.18 | C12: 66975.128
A13: 46289 | B13: 152330.62 | C13: 67523.175
A14: 46290 | B14: 157334.39 | C14: 68108.672
A15: 46291 | B15: 149175.61 | C15: 70082.435
... A33: 46309 | B33: 148729.41 | C33: 59184.499
A34: Grand Total | B34: 4468137.1 | C34: 1940510.1

Sheet Daily_Pivot
B3: ThemePark | C3: Hotel | D3: CCP | E3: HCCP
A4: 45944 | B4: 148128.63 | C4: 68731.23 | D4: 93862.874 | E4: 12557.227
A5: 46309 | B5: 148729.41 | C5: 59184.499 | D5: 65207.915 | E5: 16804.44
A6: Grand Total | B6: 296858.04 | C6: 127915.73 | D6: 159070.79 | E6: 29361.668 | S6: Area | T6: Normal daily usage (before park & hotel closure) | U6: Current daily usage | V6: Difference in %
S7: Date | T7: =A4 -> 45944 | U7: =A5 -> 46309
S8: =B3 -> ThemePark | T8: =VALUE($B$4) -> 148128.63 | U8: =VALUE($B$5) -> 148729.41 | V8: =(T8-U8)/T8 -> -0.0040557676
S9: =C3 -> Hotel | T9: =VALUE($C$4) -> 68731.23 | U9: =VALUE($C$5) -> 59184.499 | V9: =(T9-U9)/T9 -> 0.13889946
S10: =D3 -> CCP | T10: =VALUE($D$4) -> 93862.874 | U10: =VALUE($D$5) -> 65207.915 | V10: =(T10-U10)/T10 -> 0.30528534
S11: =E3 -> HCCP | T11: =VALUE($E$4) -> 12557.227 | U11: =VALUE($E$5) -> 16804.44 | V11: =(T11-U11)/T11 -> -0.33822852
S12: Total | T12: =SUM(T8:T11) -> 323279.97 | U12: =SUM(U8:U11) -> 289926.26 | V12: =(T12-U12)/T12 -> 0.10317281

Sheet Hotel_Pivot
A1: 30 Days | B1: TRUE
A3: Row Labels | B3: DHH kWh | C3: DLH kWh | D3: DEL kWh
A4: 46280 | B4: 19178.146 | C4: 25124.2 | D4: 21530.875
A5: 46281 | B5: 19421.889 | C5: 11994.34 | D5: 21546.375
A6: 46282 | B6: 19522.693 | C6: 3758 | D6: 21825.125
A7: 46283 | B7: 19869.17 | C7: 2787 | D7: 21967
A8: 46284 | B8: 20264.9 | C8: 12785.794 | D8: 22294.375
A9: 46285 | B9: 20410.699 | C9: 26312.906 | D9: 22594.25
A10: 46286 | B10: 20185.397 | C10: 25697.722 | D10: 22430.5
A11: 46287 | B11: 20168.396 | C11: 26487.188 | D11: 22168.5
A12: 46288 | B12: 19719.173 | C12: 25237.955 | D12: 22018
A13: 46289 | B13: 20182.432 | C13: 25187.243 | D13: 22153.5
A14: 46290 | B14: 20343.908 | C14: 25420.389 | D14: 22344.375
A15: 46291 | B15: 20965.156 | C15: 26686.029 | D15: 22431.25
... A33: 46309 | B33: 20355.301 | C33: 16861.948 | D33: 21967.25
A34: Grand Total | B34: 606601.71 | C34: 679136.04 | D34: 661317.38

Sheet Park vs Hotel_Pivot
A3: Row Labels | B3: ThemePark + CCP | C3: Hotel + HCCP | H3: Normal daily usage (before park & hotel closure) | I3: Current daily usage | J3: Difference in %
A4: 2025 | G4: Date | H4: =A5 -> Oct | I4: =A7 -> Oct
A5: Oct | B5: 6770571.2 | C5: 2482871.8 | G5: Park + CCP | H5: =VALUE($B$5) -> 6770571.2 | I5: =VALUE($B$7) -> 2957539.1 | J5: =(H5-I5)/H5 -> 0.56317731
A6: 2026 | G6: Hotel + HCCP | H6: =VALUE($C$5) -> 2482871.8 | I6: =VALUE($C$7) -> 1157489.2 | J6: =(H6-I6)/H6 -> 0.53381032
A7: Oct | B7: 2957539.1 | C7: 1157489.2
A8: Grand Total | B8: 9728110.3 | C8: 3640361.1
G9: Total | H9: =SUM(H5:H8) -> 9253443.1 | I9: =SUM(I5:I8) -> 4115028.3 | J9: =(H9-I9)/H9 -> 0.5552976
G12: =A4&A5 -> 2025Oct

Sheet Park vs Hotel
A1: Date | B1: 30 Days | C1: Total Power Consumption of ThemePark (kWh) | D1: Total Power Consumption of hotel (kWh)
A2: 43282 | B2: =AND(A2>=(TODAY()-30),A2<TODAY()) -> FALSE | C2: =Data!C2+Data!E2 -> 216242.22 | D2: =Data!D2+Data!F2 -> 103217.38
A3: 43283 | B3: =AND(A3>=(TODAY()-30),A3<TODAY()) -> FALSE | C3: =Data!C3+Data!E3 -> 213705.84 | D3: =Data!D3+Data!F3 -> 101754.75
A4: 43284 | B4: =AND(A4>=(TODAY()-30),A4<TODAY()) -> FALSE | C4: =Data!C4+Data!E4 -> 220671.06 | D4: =Data!D4+Data!F4 -> 98457.75
A5: 43285 | B5: =AND(A5>=(TODAY()-30),A5<TODAY()) -> FALSE | C5: =Data!C5+Data!E5 -> 216003.69 | D5: =Data!D5+Data!F5 -> 97422.125
A6: 43286 | B6: =AND(A6>=(TODAY()-30),A6<TODAY()) -> FALSE | C6: =Data!C6+Data!E6 -> 217037.53 | D6: =Data!D6+Data!F6 -> 98512.625
A7: 43287 | B7: =AND(A7>=(TODAY()-30),A7<TODAY()) -> FALSE | C7: =Data!C7+Data!E7 -> 218508.81 | D7: =Data!D7+Data!F7 -> 101319.38
A8: 43288 | B8: =AND(A8>=(TODAY()-30),A8<TODAY()) -> FALSE | C8: =Data!C8+Data!E8 -> 211278.61 | D8: =Data!D8+Data!F8 -> 102697.62
A9: 43289 | B9: =AND(A9>=(TODAY()-30),A9<TODAY()) -> FALSE | C9: =Data!C9+Data!E9 -> 207239.47 | D9: =Data!D9+Data!F9 -> 99601.875
A10: 43290 | B10: =AND(A10>=(TODAY()-30),A10<TODAY()) -> FALSE | C10: =Data!C10+Data!E10 -> 211730.87 | D10: =Data!D10+Data!F10 -> 94446.125
A11: 43291 | B11: =AND(A11>=(TODAY()-30),A11<TODAY()) -> FALSE | C11: =Data!C11+Data!E11 -> 209633.23 | D11: =Data!D11+Data!F11 -> 95351.75
A12: 43292 | B12: =AND(A12>=(TODAY()-30),A12<TODAY()) -> FALSE | C12: =Data!C12+Data!E12 -> 213371.1 | D12: =Data!D12+Data!F12 -> 94478.875
A13: 43293 | B13: =AND(A13>=(TODAY()-30),A13<TODAY()) -> FALSE | C13: =Data!C13+Data!E13 -> 211112.71 | D13: =Data!D13+Data!F13 -> 95003.75
... A1980: 45260 | B1980: =AND(A1980>=(TODAY()-30),A1980<TODAY()) -> FALSE | C1980: =Data!C1980+Data!E1980 -> 184338.65 | D1980: =Data!D1980+Data!F1980 -> 69900.865
A1981: 45261 | B1981: =AND(A1981>=(TODAY()-30),A1981<TODAY()) -> FALSE | C1981: =Data!C1981+Data!E1981 -> 161991.76 | D1981: =Data!D1981+Data!F1981 -> 71087.055 | F1981: SS205A PMCS Data Loss After Replace Meter
A1982: 45262 | B1982: =AND(A1982>=(TODAY()-30),A1982<TODAY()) -> FALSE | C1982: =Data!C1982+Data!E1982 -> 160183.23 | D1982: =Data!D1982+Data!F1982 -> 72248.611 | F1982: SS205A PMCS Data Loss After Replace Meter
A1983: 45263 | B1983: =AND(A1983>=(TODAY()-30),A1983<TODAY()) -> FALSE | C1983: =Data!C1983+Data!E1983 -> 172461.49 | D1983: =Data!D1983+Data!F1983 -> 71499.269
A1984: 45264 | B1984: =AND(A1984>=(TODAY()-30),A1984<TODAY()) -> FALSE | C1984: =Data!C1984+Data!E1984 -> 172460.65 | D1984: =Data!D1984+Data!F1984 -> 69428.894
A1985: 45265 | B1985: =AND(A1985>=(TODAY()-30),A1985<TODAY()) -> FALSE | C1985: =Data!C1985+Data!E1985 -> 128939.01 | D1985: =Data!D1985+Data!F1985 -> 49134.408
A1986: 45266 | B1986: =AND(A1986>=(TODAY()-30),A1986<TODAY()) -> FALSE | C1986: =Data!C1986+Data!E1986 -> 165004.21 | D1986: =Data!D1986+Data!F1986 -> 69832.68
A1987: 45267 | B1987: =AND(A1987>=(TODAY()-30),A1987<TODAY()) -> FALSE | C1987: =Data!C1987+Data!E1987 -> 163024.84 | D1987: =Data!D1987+Data!F1987 -> 70564.587
A1988: 45268 | B1988: =AND(A1988>=(TODAY()-30),A1988<TODAY()) -> FALSE | C1988: =Data!C1988+Data!E1988 -> 172318.8 | D1988: =Data!D1988+Data!F1988 -> 71146.946
A1989: 45269 | B1989: =AND(A1989>=(TODAY()-30),A1989<TODAY()) -> FALSE | C1989: =Data!C1989+Data!E1989 -> 196319.13 | D1989: =Data!D1989+Data!F1989 -> 71986.753
A1990: 45270 | B1990: =AND(A1990>=(TODAY()-30),A1990<TODAY()) -> FALSE | C1990: =Data!C1990+Data!E1990 -> 202463.21 | D1990: =Data!D1990+Data!F1990 -> 71891.31
A1991: 45271 | B1991: =AND(A1991>=(TODAY()-30),A1991<TODAY()) -> FALSE | C1991: =Data!C1991+Data!E1991 -> 209139.62 | D1991: =Data!D1991+Data!F1991 -> 71250.867
A1992: 45272 | B1992: =AND(A1992>=(TODAY()-30),A1992<TODAY()) -> FALSE | C1992: =Data!C1992+Data!E1992 -> 205191.09 | D1992: =Data!D1992+Data!F1992 -> 72070.714
A1993: 45273 | B1993: =AND(A1993>=(TODAY()-30),A1993<TODAY()) -> FALSE | C1993: =Data!C1993+Data!E1993 -> 180516.38 | D1993: =Data!D1993+Data!F1993 -> 73738.018
A1994: 45274 | B1994: =AND(A1994>=(TODAY()-30),A1994<TODAY()) -> FALSE | C1994: =Data!C1994+Data!E1994 -> 187044.38 | D1994: =Data!D1994+Data!F1994 -> 72758.985
... A3046: 46326 | B3046: =AND(A3046>=(TODAY()-30),A3046<TODAY()) -> FALSE | C3046: =Data!C3046+Data!E3046 -> 0 | D3046: =Data!D3046+Data!F3046 -> 0

Sheet Data
A1: Date | B1: 30 Days | C1: Total Power Consumption of ThemePark (kWh) | D1: Total Power Consumption of hotel (kWh) | E1: Total Power Consumption of CCP (kWh) | F1: Total Power Consumption of HCCP (kWh)
A2: 43282 | B2: =AND(A2>=(TODAY()-30),A2<TODAY()) -> FALSE | C2: =Park!X2 -> 141386.66 | D2: =Hotel!N3 -> 78475 | E2: =CCP!I2 -> 74855.562 | F2: =HCCP!F2 -> 24742.375
A3: 43283 | B3: =AND(A3>=(TODAY()-30),A3<TODAY()) -> FALSE | C3: =Park!X3 -> 137502.34 | D3: =Hotel!N4 -> 76559.125 | E3: =CCP!I3 -> 76203.5 | F3: =HCCP!F3 -> 25195.625
A4: 43284 | B4: =AND(A4>=(TODAY()-30),A4<TODAY()) -> FALSE | C4: =Park!X4 -> 143944.12 | D4: =Hotel!N5 -> 73037.875 | E4: =CCP!I4 -> 76726.938 | F4: =HCCP!F4 -> 25419.875
A5: 43285 | B5: =AND(A5>=(TODAY()-30),A5<TODAY()) -> FALSE | C5: =Park!X5 -> 141186.94 | D5: =Hotel!N6 -> 71709.625 | E5: =CCP!I5 -> 74816.75 | F5: =HCCP!F5 -> 25712.5
A6: 43286 | B6: =AND(A6>=(TODAY()-30),A6<TODAY()) -> FALSE | C6: =Park!X6 -> 142233.16 | D6: =Hotel!N7 -> 73290.875 | E6: =CCP!I6 -> 74804.375 | F6: =HCCP!F6 -> 25221.75
A7: 43287 | B7: =AND(A7>=(TODAY()-30),A7<TODAY()) -> FALSE | C7: =Park!X7 -> 141272.19 | D7: =Hotel!N8 -> 75626.375 | E7: =CCP!I7 -> 77236.625 | F7: =HCCP!F7 -> 25693
A8: 43288 | B8: =AND(A8>=(TODAY()-30),A8<TODAY()) -> FALSE | C8: =Park!X8 -> 137158.09 | D8: =Hotel!N9 -> 77706.875 | E8: =CCP!I8 -> 74120.521 | F8: =HCCP!F8 -> 24990.75
A9: 43289 | B9: =AND(A9>=(TODAY()-30),A9<TODAY()) -> FALSE | C9: =Park!X9 -> 135545.12 | D9: =Hotel!N10 -> 76341.625 | E9: =CCP!I9 -> 71694.344 | F9: =HCCP!F9 -> 23260.25
A10: 43290 | B10: =AND(A10>=(TODAY()-30),A10<TODAY()) -> FALSE | C10: =Park!X10 -> 139224.88 | D10: =Hotel!N11 -> 72975.5 | E10: =CCP!I10 -> 72505.992 | F10: =HCCP!F10 -> 21470.625
A11: 43291 | B11: =AND(A11>=(TODAY()-30),A11<TODAY()) -> FALSE | C11: =Park!X11 -> 139799.25 | D11: =Hotel!N12 -> 73474.75 | E11: =CCP!I11 -> 69833.977 | F11: =HCCP!F11 -> 21877
A12: 43292 | B12: =AND(A12>=(TODAY()-30),A12<TODAY()) -> FALSE | C12: =Park!X12 -> 140815.91 | D12: =Hotel!N13 -> 71895.375 | E12: =CCP!I12 -> 72555.195 | F12: =HCCP!F12 -> 22583.5
A13: 43293 | B13: =AND(A13>=(TODAY()-30),A13<TODAY()) -> FALSE | C13: =Park!X13 -> 140689.41 | D13: =Hotel!N14 -> 71698.5 | E13: =CCP!I13 -> 70423.305 | F13: =HCCP!F13 -> 23305.25
... A1980: 45260 | B1980: =AND(A1980>=(TODAY()-30),A1980<TODAY()) -> FALSE | C1980: =Park!X1980 -> 140093.18 | D1980: =Hotel!N1981 -> 65318.815 | E1980: =CCP!I1980 -> 44245.475 | F1980: =HCCP!F1980 -> 4582.05
A1981: 45261 | B1981: =AND(A1981>=(TODAY()-30),A1981<TODAY()) -> FALSE | C1981: =Park!X1981 -> 141233.75 | D1981: =Hotel!N1982 -> 66684.225 | E1981: =CCP!I1981 -> 20758.015 | F1981: =HCCP!F1981 -> 4402.83 | H1981: CCP (SS205A PMCS Data Loss) After Replace Meter
A1982: 45262 | B1982: =AND(A1982>=(TODAY()-30),A1982<TODAY()) -> FALSE | C1982: =Park!X1982 -> 140097 | D1982: =Hotel!N1983 -> 67879.141 | E1982: =CCP!I1982 -> 20086.225 | F1982: =HCCP!F1982 -> 4369.47 | H1982: CCP (SS205A PMCS Data Loss) After Replace Meter
A1983: 45263 | B1983: =AND(A1983>=(TODAY()-30),A1983<TODAY()) -> FALSE | C1983: =Park!X1983 -> 140380.01 | D1983: =Hotel!N1984 -> 67067.939 | E1983: =CCP!I1983 -> 32081.474 | F1983: =HCCP!F1983 -> 4431.33
A1984: 45264 | B1984: =AND(A1984>=(TODAY()-30),A1984<TODAY()) -> FALSE | C1984: =Park!X1984 -> 138935.33 | D1984: =Hotel!N1985 -> 65069.564 | E1984: =CCP!I1984 -> 33525.328 | F1984: =HCCP!F1984 -> 4359.33
A1985: 45265 | B1985: =AND(A1985>=(TODAY()-30),A1985<TODAY()) -> FALSE | C1985: =Park!X1985 -> 104515.27 | D1985: =Hotel!N1986 -> 46067.458 | E1985: =CCP!I1985 -> 24423.736 | F1985: =HCCP!F1985 -> 3066.95
A1986: 45266 | B1986: =AND(A1986>=(TODAY()-30),A1986<TODAY()) -> FALSE | C1986: =Park!X1986 -> 135277.47 | D1986: =Hotel!N1987 -> 65299.67 | E1986: =CCP!I1986 -> 29726.738 | F1986: =HCCP!F1986 -> 4533.01
A1987: 45267 | B1987: =AND(A1987>=(TODAY()-30),A1987<TODAY()) -> FALSE | C1987: =Park!X1987 -> 137631.85 | D1987: =Hotel!N1988 -> 66293.577 | E1987: =CCP!I1987 -> 25392.996 | F1987: =HCCP!F1987 -> 4271.01
A1988: 45268 | B1988: =AND(A1988>=(TODAY()-30),A1988<TODAY()) -> FALSE | C1988: =Park!X1988 -> 142469.09 | D1988: =Hotel!N1989 -> 66640.236 | E1988: =CCP!I1988 -> 29849.712 | F1988: =HCCP!F1988 -> 4506.71
A1989: 45269 | B1989: =AND(A1989>=(TODAY()-30),A1989<TODAY()) -> FALSE | C1989: =Park!X1989 -> 144895.87 | D1989: =Hotel!N1990 -> 67225.043 | E1989: =CCP!I1989 -> 51423.26 | F1989: =HCCP!F1989 -> 4761.71
A1990: 45270 | B1990: =AND(A1990>=(TODAY()-30),A1990<TODAY()) -> FALSE | C1990: =Park!X1990 -> 146436.39 | D1990: =Hotel!N1991 -> 67065.8 | E1990: =CCP!I1990 -> 56026.82 | F1990: =HCCP!F1990 -> 4825.51
A1991: 45271 | B1991: =AND(A1991>=(TODAY()-30),A1991<TODAY()) -> FALSE | C1991: =Park!X1991 -> 146908.79 | D1991: =Hotel!N1992 -> 66631.938 | E1991: =CCP!I1991 -> 62230.839 | F1991: =HCCP!F1991 -> 4618.93
A1992: 45272 | B1992: =AND(A1992>=(TODAY()-30),A1992<TODAY()) -> FALSE | C1992: =Park!X1992 -> 144941 | D1992: =Hotel!N1993 -> 65769.164 | E1992: =CCP!I1992 -> 60250.088 | F1992: =HCCP!F1992 -> 6301.55
A1993: 45273 | B1993: =AND(A1993>=(TODAY()-30),A1993<TODAY()) -> FALSE | C1993: =Park!X1993 -> 139637.05 | D1993: =Hotel!N1994 -> 66971.448 | E1993: =CCP!I1993 -> 40879.322 | F1993: =HCCP!F1993 -> 6766.57
A1994: 45274 | B1994: =AND(A1994>=(TODAY()-30),A1994<TODAY()) -> FALSE | C1994: =Park!X1994 -> 141397.61 | D1994: =Hotel!N1995 -> 65960.945 | E1994: =CCP!I1994 -> 45646.765 | F1994: =HCCP!F1994 -> 6798.04
... A3046: 46326 | B3046: =AND(A3046>=(TODAY()-30),A3046<TODAY()) -> FALSE | C3046: =Park!X3046 -> 0 | D3046: =Hotel!N3047 -> 0 | E3046: =CCP!I3046 -> 0 | F3046: =HCCP!F3046 -> 0

Sheet CCP
A1: Date | B1: SS205A_TxA (kWh) | C1: SS205A_TxB (kWh) | D1: SS205A_TxC (kWh) | E1: SS205B_TxA (kWh) | F1: SS205B_TxB (kWh) | G1: SS205B_TxC (kWh) | H1: EA8 | I1: Total Power Consumption of CCP (kWh)
A2: 43282 | B2: 15111 | C2: 17092 | D2: 3137.75 | E2: 15884 | F2: 12254 | G2: 11376.812 | I2: 74855.562
A3: 43283 | B3: 15308 | C3: 17156 | D3: 3071 | E3: 15892 | F3: 13282.5 | G3: 11494 | I3: 76203.5
A4: 43284 | B4: 15223 | C4: 17440 | D4: 3068.75 | E4: 16035 | F4: 13123 | G4: 11837.188 | I4: 76726.938
A5: 43285 | B5: 15780 | C5: 18422 | D5: 2757.5 | E5: 16135 | F5: 12890.5 | G5: 8831.75 | I5: 74816.75
A6: 43286 | B6: 14863 | C6: 17957 | D6: 3093.25 | E6: 15362 | F6: 13211 | G6: 10318.125 | I6: 74804.375
A7: 43287 | B7: 15359 | C7: 17360.5 | D7: 3182.25 | E7: 15931 | F7: 13781.5 | G7: 11622.375 | I7: 77236.625
A8: 43288 | B8: 15080 | C8: 16950.5 | D8: 3092.75 | E8: 15705.646 | F8: 11949 | G8: 11342.625 | I8: 74120.521
A9: 43289 | B9: 14805 | C9: 16300 | D9: 3048 | E9: 15417.344 | F9: 11173 | G9: 10951 | I9: 71694.344
A10: 43290 | B10: 14588 | C10: 16815.5 | D10: 3027.75 | E10: 15280.867 | F10: 12004.5 | G10: 10789.375 | I10: 72505.992
A11: 43291 | B11: 14605 | C11: 18127 | D11: 2615.25 | E11: 14978.727 | F11: 11531.5 | G11: 7976.5 | I11: 69833.977
A12: 43292 | B12: 11841 | C12: 17854.5 | D12: 4077.5 | E12: 15539.945 | F12: 12080 | G12: 11162.25 | I12: 72555.195
A13: 43293 | B13: 3074 | C13: 19466.5 | D13: 6960 | E13: 14380.68 | F13: 13102.5 | G13: 13439.625 | I13: 70423.305
... A443: 43723 | B443: 13774 | C443: 19200.625 | D443: 3334 | E443: 7460 | F443: 15617.75 | G443: 7366 | I443: 66752.375
A444: =1 + A443 -> 43724 | B444: 13811.25 | C444: 18245.625 | D444: 3252 | E444: 8708.5 | F444: 13978.5 | G444: 10494 | I444: 68489.875
A445: =1 + A444 -> 43725 | B445: 13812.25 | C445: 14743.312 | D445: 3079 | E445: 12568.5 | F445: 6150.25 | G445: 14034 | I445: 64387.312
A446: =1 + A445 -> 43726 | B446: 13809 | C446: 14594.812 | D446: 3090.5 | E446: 12490.5 | F446: 7434.25 | G446: 14063.25 | I446: 65482.312
A447: 43727 | B447: 13381 | C447: 12876.875 | D447: 2905 | E447: 12200.5 | F447: 2720.25 | G447: 13535.75 | I447: 57619.375
A448: 43728 | B448: 10462 | C448: 10305.938 | D448: 2210 | E448: 11330 | F448: 3593.5 | G448: 12941.25 | I448: 50842.688
A449: 43729 | B449: 8709.75 | C449: 6623.6875 | D449: 1489.5 | E449: 11422.5 | F449: 1628.5 | G449: 13015.5 | I449: 42889.438
A450: 43730 | B450: 7315.5 | C450: 6417 | D450: 1196.5 | E450: 10868.5 | F450: 1630 | G450: 12611.25 | I450: 40038.75
A451: 43731 | B451: 2927.5 | C451: 13288.188 | D451: 1490.5 | E451: 11553 | F451: 1652.75 | G451: 13114.25 | I451: 44026.188
A452: 43732 | B452: 2971 | C452: 14394.375 | D452: 1921 | E452: 11956 | F452: 5463 | G452: 13499.5 | I452: 50204.875
A453: 43733 | B453: 2997.75 | C453: 14501.5 | D453: 1938 | E453: 10557.5 | F453: 6639.75 | G453: 13421.25 | I453: 50055.75
A454: 43734 | B454: 3089 | C454: 17258.875 | D454: 2102.5 | E454: 5555 | F454: 9301.5 | G454: 13201.25 | I454: 50508.125
A455: 43735 | B455: 6414.5 | C455: 17391.25 | D455: 1949 | E455: 8720 | F455: 3346.5 | G455: 13697.25 | I455: 51518.5
A456: 43736 | B456: 2908.75 | C456: 11329.875 | D456: 2034 | E456: 12265 | F456: 11028 | G456: 13621 | I456: 53186.625
A457: 43737 | B457: 2851.25 | C457: 12595 | D457: 2298 | E457: 10091 | F457: 15373.75 | G457: 14252.5 | I457: 57461.5
A458: 43738 | B458: 2864.5 | C458: 12046.375 | D458: 2259 | E458: 9623.5 | F458: 13501.5 | G458: 13603.25 | I458: 53898.125
... A626: 43906 | B626: 16572 | C626: 0 | D626: 2847.672 | E626: 2848 | F626: 377 | G626: 34.5 | I626: 22679.172
A627: 43907 | B627: 16574 | C627: 0 | D627: =D573-D477 -> 2174 | E627: 2847 | F627: 377 | G627: 35 | I627: 22007
A628: 43908 | B628: 16682 | C628: 0 | D628: 2830.609 | E628: 2902.5 | F628: 367.25 | G628: 34 | I628: 22816.359
A629: 43909 | B629: 17576.5 | C629: 0 | D629: 2904.797 | E629: 1415 | F629: 427.75 | G629: 1658.5 | I629: 23982.547
A630: 43910 | B630: 17416.5 | C630: 0 | D630: 2852.313 | E630: 174.5 | F630: 366.25 | G630: 3014 | I630: 23823.563
A631: 43911 | B631: 17885 | C631: 0 | D631: 2849.813 | E631: 168 | F631: 442 | G631: 3082 | I631: 24426.813
A632: 43912 | B632: 18882 | C632: 0 | D632: 2918.312 | E632: 157.5 | F632: 758.5 | G632: 3123 | I632: 25839.312
A633: 43913 | B633: 20631.5 | C633: 0 | D633: 3061.516 | E633: 179 | F633: 959.25 | G633: 3258 | I633: 25027.75
A634: 43914 | B634: 18482 | C634: 0 | D634: 2892.25 | E634: 175 | F634: 2372.25 | G634: 3087.5 | I634: 27009
A635: 43915 | B635: 8534 | C635: 0 | D635: 9622.593 | E635: 1917 | F635: 3302 | G635: 2990 | I635: 26365.593
A636: 43916 | B636: 2474 | C636: 0 | D636: 13562.36 | E636: 3522.5 | F636: 3463.5 | G636: 1837 | I636: 24859.36
...

Sheet HCCP
A1: Date | B1: SS303A_TxA (kWh) | C1: SS303B_TxD2 (kWh) | D1: SS303B_TxD3 (kWh) | E1: SS303B_TxD3_C12 CSB | F1: Total Power Consumption of HCCP (kWh)
A2: 43282 | B2: 2702.5 | C2: 4604.375 | D2: 17435.5 | F2: 24742.375
A3: 43283 | B3: 2738.5 | C3: 4515.625 | D3: 17941.5 | F3: 25195.625
A4: 43284 | B4: 2817.75 | C4: 4374.125 | D4: 18228 | F4: 25419.875
A5: 43285 | B5: 2910.25 | C5: 4500.75 | D5: 18301.5 | F5: 25712.5
A6: 43286 | B6: 2874 | C6: 4281.75 | D6: 18066 | F6: 25221.75
A7: 43287 | B7: 2870.75 | C7: 4519.75 | D7: 18302.5 | F7: 25693
A8: 43288 | B8: 2744.75 | C8: 4363.5 | D8: 17882.5 | F8: 24990.75
A9: 43289 | B9: 2711.25 | C9: 4337.5 | D9: 16211.5 | F9: 23260.25
A10: 43290 | B10: 2555 | C10: 4343.125 | D10: 14572.5 | F10: 21470.625
A11: 43291 | B11: 2733.75 | C11: 4128.75 | D11: 15014.5 | F11: 21877
A12: 43292 | B12: 2618.5 | C12: 4267 | D12: 15698 | F12: 22583.5
A13: 43293 | B13: 2754.5 | C13: 4276.75 | D13: 16274 | F13: 23305.25
... A2011: 45291 | B2011: 3386.49 | C2011: 60.44 | D2011: 1005.7 | F2011: 4452.63
A2012: 45292 | B2012: 3393.51 | C2012: 60.42 | D2012: 947.13 | E2012: 543.125 | F2012: 3857.935
A2013: 45293 | B2013: 3371.6 | C2013: 298.87 | D2013: 971.45 | E2013: 602.5 | F2013: 4039.42
A2014: 45294 | B2014: 2966.1 | C2014: 54.12 | D2014: 891.95 | E2014: 544.25 | F2014: 3367.92
A2015: 45295 | B2015: 1461.15 | C2015: 57.87 | D2015: 792.38 | E2015: 540.875 | F2015: 1770.525
A2016: 45296 | B2016: 1404.56 | C2016: 62.22 | D2016: 809.68 | E2016: 543.875 | F2016: 1732.585
A2017: 45297 | B2017: 1536.1 | C2017: 61.32 | D2017: 825.86 | E2017: 544.375 | F2017: 1878.905
A2018: 45298 | B2018: 1535.62 | C2018: 60.32 | D2018: 818.19 | E2018: 557.25 | F2018: 1856.88
A2019: 45299 | B2019: 1539.72 | C2019: 60.29 | D2019: 807.6 | E2019: 552 | F2019: 1855.61
A2020: 45300 | B2020: 1530.46 | C2020: 61.5 | D2020: 838.9 | E2020: 550.75 | F2020: 1880.11
A2021: 45301 | B2021: 1561.39 | C2021: 60.41 | D2021: 821.64 | E2021: 542.875 | F2021: 1900.565
A2022: 45302 | B2022: 1581.09 | C2022: 54.64 | D2022: 806.23 | E2022: 564.5 | F2022: 1877.46
A2023: 45303 | B2023: 1551.83 | C2023: 64.91 | D2023: 817.54 | E2023: 566.75 | F2023: 1867.53
... A3029: 46309 | B3029: 2034.1 | C3029: 3130.72 | D3029: 12247.37 | E3029: 607.75 | F3029: 16804.44

Sheet Hotel
B1: DHH | E1: DLH | J1: DEL
A2: Date | B2: SS301_TxA (kWh) | C2: SS301_TxB (kWh) | D2: SS301_TxC (kWh) | E2: SS302A_TxA1 (kWh) | F2: SS302A_TxA2 (kWh) | G2: SS302A_TxC5 (kWh) | H2: SS302B_TxB4 (kWh) | I2: SS302C_TxA3 (kWh) | J2: SS304A_TxA (kWh) | K2: SS304A_TxB (kWh) | L2: SS304B_TxC (kWh) | M2: SS304B_TxD (kWh) | N2: Total Power Consumption of hotel (kWh) | O2: Occupancy | P2: 30 Days | Q2: DHH Total kWh | R2: DLH Total Sum | S2: DEL Total Sum
A3: 43282 | B3: 9955.75 | C3: 4283 | D3: 7636 | E3: 7386 | F3: 8824 | G3: 103.5 | H3: 9941.75 | I3: 4736 | J3: 7557.25 | K3: 6561.25 | L3: 6132 | M3: 5358.5 | N3: 78475 | P3: =AND(A3>=(TODAY()-30),A3<TODAY()) -> FALSE | Q3: 21874.75 | R3: 30991.25 | S3: 25609
A4: 43283 | B4: 9921.5 | C4: 4278 | D4: 7472 | E4: 6853.5 | F4: 8619 | G4: 100 | H4: 9869.375 | I4: 4509.75 | J4: 7375 | K4: 6509.25 | L4: 5753 | M4: 5298.75 | N4: 76559.125 | P4: =AND(A4>=(TODAY()-30),A4<TODAY()) -> FALSE | Q4: 21671.5 | R4: 29951.625 | S4: 24936
A5: 43284 | B5: 9861 | C5: 4214 | D5: 6962.5 | E5: 5698 | F5: 8247 | G5: 102.5 | H5: 9707.375 | I5: 4120.25 | J5: 7046.75 | K5: 6217.25 | L5: 5587.75 | M5: 5273.5 | N5: 73037.875 | P5: =AND(A5>=(TODAY()-30),A5<TODAY()) -> FALSE | Q5: 21037.5 | R5: 27875.125 | S5: 24125.25
A6: 43285 | B6: 9726.5 | C6: 4040 | D6: 6785 | E6: 5523.5 | F6: 8138 | G6: 107 | H6: 9595.375 | I6: 4161.5 | J6: 6893.25 | K6: 6107.5 | L6: 5535.25 | M6: 5096.75 | N6: 71709.625 | P6: =AND(A6>=(TODAY()-30),A6<TODAY()) -> FALSE | Q6: 20551.5 | R6: 27525.375 | S6: 23632.75
A7: 43286 | B7: 9879.5 | C7: 4114 | D7: 6850 | E7: 5977.5 | F7: 8266 | G7: 103 | H7: 9769.625 | I7: 4437.25 | J7: 6944 | K7: 6139.5 | L7: 5597.25 | M7: 5213.25 | N7: 73290.875 | P7: =AND(A7>=(TODAY()-30),A7<TODAY()) -> FALSE | Q7: 20843.5 | R7: 28553.375 | S7: 23894
A8: 43287 | B8: 9949.25 | C8: 4234 | D8: 6955.5 | E8: 7198 | F8: 8602 | G8: 110 | H8: 9665.875 | I8: 4680.25 | J8: 7168.75 | K8: 6167 | L8: 5698 | M8: 5197.75 | N8: 75626.375 | P8: =AND(A8>=(TODAY()-30),A8<TODAY()) -> FALSE | Q8: 21138.75 | R8: 30256.125 | S8: 24231.5
A9: 43288 | B9: 10128.5 | C9: 4294 | D9: 7529 | E9: 7270 | F9: 8786 | G9: 93 | H9: 9902.375 | I9: 4701 | J9: 7387.75 | K9: 6413.75 | L9: 5857.75 | M9: 5343.75 | N9: 77706.875 | P9: =AND(A9>=(TODAY()-30),A9<TODAY()) -> FALSE | Q9: 21951.5 | R9: 30752.375 | S9: 25003
A10: 43289 | B10: 10130.5 | C10: 4191 | D10: 7441.5 | E10: 6764.5 | F10: 8583 | G10: 83.5 | H10: 9928.625 | I10: 4290 | J10: 7450.5 | K10: 6453.5 | L10: 5752.25 | M10: 5272.75 | N10: 76341.625 | P10: =AND(A10>=(TODAY()-30),A10<TODAY()) -> FALSE | Q10: 21763 | R10: 29649.625 | S10: 24929
A11: 43290 | B11: 10053 | C11: 4139 | D11: 6859 | E11: 6124 | F11: 8214 | G11: 82.5 | H11: 9511.75 | I11: 4066 | J11: 7054.75 | K11: 6078.5 | L11: 5603.5 | M11: 5189.5 | N11: 72975.5 | P11: =AND(A11>=(TODAY()-30),A11<TODAY()) -> FALSE | Q11: 21051 | R11: 27998.25 | S11: 23926.25
A12: 43291 | B12: 9888.75 | C12: 4129 | D12: 6923 | E12: 6333.5 | F12: 8253 | G12: 81 | H12: 9535.75 | I12: 4112.5 | J12: 7288.75 | K12: 6049.25 | L12: 5668.5 | M12: 5211.75 | N12: 73474.75 | P12: =AND(A12>=(TODAY()-30),A12<TODAY()) -> FALSE | Q12: 20940.75 | R12: 28315.75 | S12: 24218.25
A13: 43292 | B13: 9715.25 | C13: 4414 | D13: 6077.5 | E13: 6082.5 | F13: 8167 | G13: 89 | H13: 9562.375 | I13: 4108 | J13: 7092 | K13: 5984.75 | L13: 5578.5 | M13: 5024.5 | N13: 71895.375 | P13: =AND(A13>=(TODAY()-30),A13<TODAY()) -> FALSE | Q13: 20206.75 | R13: 28008.875 | S13: 23679.75
A14: 43293 | B14: 9688.75 | C14: 4342 | D14: 6250 | E14: 5926.5 | F14: 8245 | G14: 95 | H14: 9571.5 | I14: 4026.75 | J14: 7085.25 | K14: 6012 | L14: 5407.5 | M14: 5048.25 | N14: 71698.5 | P14: =AND(A14>=(TODAY()-30),A14<TODAY()) -> FALSE | Q14: 20280.75 | R14: 27864.75 | S14: 23553
... A429: 43708 | B429: 9202.5 | C429: 3073.5 | D429: 6561 | E429: 7372.4375 | F429: 8281.75 | G429: 45.5 | H429: 9290 | I429: 4250.5 | J429: 6398 | K429: 5565.5 | L429: 4568 | M429: 4558.5 | N429: 69167.188 | P429: =AND(A429>=(TODAY()-30),A429<TODAY()) -> FALSE | Q429: 18837 | R429: 29240.188 | S429: 21090
A430: 43709 | B430: 9160 | C430: 3224.875 | D430: 6327.5 | E430: 6467.1875 | F430: 8466.5 | G430: 48.5 | H430: 9260 | I430: 3998.5 | J430: 6367.5 | K430: 5581 | L430: 4487 | M430: 4332 | N430: 67720.562 | O430: 24.571429 | P430: =AND(A430>=(TODAY()-30),A430<TODAY()) -> FALSE | Q430: 18712.375 | R430: 28240.688 | S430: 20767.5
A431: 43710 | B431: 9189.5 | C431: 3112.75 | D431: 6003 | E431: 6409.5625 | F431: 8204.75 | G431: 46.5 | H431: 8954.5 | I431: 4202 | J431: 6244 | K431: 5264 | L431: 4484.5 | M431: 4255 | N431: 66370.062 | O431: 20.228571 | P431: =AND(A431>=(TODAY()-30),A431<TODAY()) -> FALSE | Q431: 18305.25 | R431: 27817.312 | S431: 20247.5
A432: 43711 | B432: 9033 | C432: 2883.375 | D432: 5822 | E432: 6575.8125 | F432: 7809.5 | G432: 56 | H432: 8678 | I432: 3772 | J432: 6082 | K432: 4935.5 | L432: 4320 | M432: 4112 | N432: 64079.188 | O432: 20.857143 | P432: =AND(A432>=(TODAY()-30),A432<TODAY()) -> FALSE | Q432: 17738.375 | R432: 26891.312 | S432: 19449.5
A433: 43712 | B433: 9060.5 | C433: 2882.5 | D433: 5767.5 | E433: 6175.1875 | F433: 7779.75 | G433: 51 | H433: 8570.5 | I433: 3649 | J433: 5824 | K433: 4946.5 | L433: 4284 | M433: 4108 | N433: 63098.438 | O433: 22.8 | P433: =AND(A433>=(TODAY()-30),A433<TODAY()) -> FALSE | Q433: 17710.5 | R433: 26225.438 | S433: 19162.5
A434: 43713 | B434: 9126.5 | C434: 3036.75 | D434: 5729.5 | E434: 6303.375 | F434: 7796 | G434: 48 | H434: 8516 | I434: 3499.5 | J434: 5880 | K434: 4972.5 | L434: 4324 | M434: 4113.5 | N434: 63345.625 | O434: 25.771429 | P434: =AND(A434>=(TODAY()-30),A434<TODAY()) -> FALSE | Q434: 17892.75 | R434: 26162.875 | S434: 19290
A435: 43714 | B435: 9096.5 | C435: 3007 | D435: 5955.5 | E435: 5992.5 | F435: 7613.25 | G435: 56.5 | H435: 8832.5 | I435: 3279 | J435: 5894 | K435: 5021 | L435: 4346.5 | M435: 4165 | N435: 63259.25 | O435: 24.628571 | P435: =AND(A435>=(TODAY()-30),A435<TODAY()) -> FALSE | Q435: 18059 | R435: 25773.75 | S435: 19426.5
A436: 43715 | B436: 8865.5 | C436: 3044.75 | D436: 6065 | E436: 6519.625 | F436: 7890.25 | G436: 62.5 | H436: 9200.5 | I436: 3561 | J436: 6122 | K436: 5299.5 | L436: 4405 | M436: 4311.5 | N436: 65347.125 | O436: 40.342857 | P436: =AND(A436>=(TODAY()-30),A436<TODAY()) -> FALSE | Q436: 17975.25 | R436: 27233.875 | S436: 20138
A437: 43716 | B437: 8721 | C437: 3140.625 | D437: 6290 | E437: 7044.5625 | F437: 8140.5 | G437: 65.5 | H437: 9076.5 | I437: 3542 | J437: 5973 | K437: 5309 | L437: 4346 | M437: 4319 | N437: 65967.688 | O437: 24.114286 | P437: =AND(A437>=(TODAY()-30),A437<TODAY()) -> FALSE | Q437: 18151.625 | R437: 27869.062 | S437: 19947
A438: 43717 | B438: 8619 | C438: 2979.375 | D438: 5704 | E438: 6243.5625 | F438: 7626 | G438: 70.5 | H438: 8807 | I438: 3254 | J438: 5749.5 | K438: 4942 | L438: 4357.5 | M438: 4227.5 | N438: 62579.938 | O438: 22.4 | P438: =AND(A438>=(TODAY()-30),A438<TODAY()) -> FALSE | Q438: 17302.375 | R438: 26001.062 | S438: 19276.5
A439: 43718 | B439: 8505.5 | C439: 2905 | D439: 5775.5 | E439: 6057.5625 | F439: 7563.75 | G439: 71 | H439: 8669 | I439: 3583 | J439: 5861.5 | K439: 4878.5 | L439: 4333 | M439: 4222 | N439: 62425.312 | O439: 22.057143 | P439: =AND(A439>=(TODAY()-30),A439<TODAY()) -> FALSE | Q439: 17186 | R439: 25944.312 | S439: 19295
A440: 43719 | B440: 8454.5 | C440: 2992.125 | D440: 5666.5 | E440: 6231.0625 | F440: 7485.25 | G440: 72 | H440: 8656 | I440: 3467.5 | J440: 5922.5 | K440: 4975 | L440: 4277.5 | M440: 4195.5 | N440: 62395.438 | O440: 25.085714 | P440: =AND(A440>=(TODAY()-30),A440<TODAY()) -> FALSE | Q440: 17113.125 | R440: 25911.812 | S440: 19370.5
A441: 43720 | B441: 8361 | C441: 3031.75 | D441: 5636 | E441: 6371.0625 | F441: 7540.25 | G441: 74.5 | H441: 8626 | I441: 3567.5 | J441: 5987 | K441: 5176 | L441: 4406.5 | M441: 4278 | N441: 63055.562 | O441: 33.371429 | P441: =AND(A441>=(TODAY()-30),A441<TODAY()) -> FALSE | Q441: 17028.75 | R441: 26179.312 | S441: 19847.5
... A628: 43907 | B628: 2656 | C628: 404 | D628: 617 | E628: 4448.875 | F628: 6001 | G628: 10.5 | H628: 6323.5 | I628: 2785.5 | J628: 2785.5 | K628: 1295 | L628: 1338.5 | M628: 1848 | N628: 30513.375 | O628: 0.8 | P628: =AND(A628>=(TODAY()-30),A628<TODAY()) -> FALSE | Q628: 3677 | R628: 19569.375 | S628: 7267
A629: 43908 | B629: 2660 | C629: 428.625 | D629: 639 | E629: 4425.125 | F629: 5978.5 | G629: 5.5 | H629: 6365 | I629: 2811 | J629: 2811 | K629: 1337.5 | L629: 1258.5 | M629: 1875 | N629: 30594.75 | O629: Loss | P629: =AND(A629>=(TODAY()-30),A629<TODAY()) -> FALSE | Q629: 3727.625 | R629: 19585.125 | S629: 7282
A630: 43909 | B630: 2761 | C630: 499.875 | D630: 629 | E630: 4313.125 | F630: 5832.5 | G630: 2.5 | H630: 6288 | I630: 2933.5 | J630: 2933.5 | K630: 1330 | L630: 1248 | M630: 1791 | N630: 30562 | O630: 0.7 | P630: =AND(A630>=(TODAY()-30),A630<TODAY()) -> FALSE | Q630: 3889.875 | R630: 19369.625 | S630: 7302.5
A631: 43910 | B631: 2688 | C631: 446.75 | D631: 619 | E631: 4350.125 | F631: 6017 | G631: 4 | H631: 6208.5 | I631: 2949.5 | J631: 2949.5 | K631: 1333.5 | L631: 1139.5 | M631: 1785.5 | N631: 30490.875 | O631: 0.7 | P631: =AND(A631>=(TODAY()-30),A631<TODAY()) -> FALSE | Q631: 3753.75 | R631: 19529.125 | S631: 7208
A632: 43911 | B632: 2607 | C632: 387.25 | D632: 534 | E632: 4316.25 | F632: 6317.5 | G632: 5 | H632: 6424.5 | I632: 2951.5 | J632: 2951.5 | K632: 1320 | L632: 1113 | M632: 1784.5 | N632: 30712 | O632: Loss | P632: =AND(A632>=(TODAY()-30),A632<TODAY()) -> FALSE | Q632: 3528.25 | R632: 20014.75 | S632: 7169
A633: 43912 | B633: 2545 | C633: 391.5 | D633: 571 | E633: 4243.125 | F633: 6162.5 | G633: 14 | H633: 6335.5 | I633: 2962.5 | J633: 2962.5 | K633: 1327.5 | L633: 1091.5 | M633: 1759 | N633: 30365.625 | O633: 1 | P633: =AND(A633>=(TODAY()-30),A633<TODAY()) -> FALSE | Q633: 3507.5 | R633: 19717.625 | S633: 7140.5
A634: 43913 | B634: 2640 | C634: 475.5 | D634: 554 | E634: 4236.25 | F634: 5939 | G634: 20.5 | H634: 6167.5 | I634: 2903 | J634: 2903 | K634: 1326.5 | L634: 1227 | M634: 1827.5 | N634: 30219.75 | O634: 0.9 | P634: =AND(A634>=(TODAY()-30),A634<TODAY()) -> FALSE | Q634: 3669.5 | R634: 19266.25 | S634: 7284
A635: 43914 | B635: 2695 | C635: 521.125 | D635: 560 | E635: 4296 | F635: 5692.5 | G635: 22.5 | H635: 6157.5 | I635: 2847 | J635: 2847 | K635: 1322 | L635: 1108 | M635: 1824 | N635: 29892.625 | O635: 0.7 | P635: =AND(A635>=(TODAY()-30),A635<TODAY()) -> FALSE | Q635: 3776.125 | R635: 19015.5 | S635: 7101
A636: 43915 | B636: 2637 | C636: 493.625 | D636: 562 | E636: 4327.875 | F636: 5661.5 | G636: 23 | H636: 6172.5 | I636: 2771.5 | J636: 2771.5 | K636: 1330 | L636: 1091 | M636: 1750 | N636: 29591.5 | O636: 0.5 | P636: =AND(A636>=(TODAY()-30),A636<TODAY()) -> FALSE | Q636: 3692.625 | R636: 18956.375 | S636: 6942.5
A637: 43916 | B637: 2608 | C637: 490.5 | D637: 555 | E637: 4318.375 | F637: 5827.5 | G637: 23.5 | H637: 6187.5 | I637: 2814.5 | J637: 2814.5 | K637: 1331 | L637: 1068 | M637: 1769 | N637: 29807.375 | O637: 0.9 | P637: =AND(A637>=(TODAY()-30),A637<TODAY()) -> FALSE | Q637: 3653.5 | R637: 19171.375 | S637: 6982.5
A638: 43917 | B638: 2628 | C638: 520.75 | D638: 565 | E638: 4410.375 | F638: 5878 | G638: 25 | H638: 6250.5 | I638: 2844 | J638: 2844 | K638: 1336.5 | L638: 1118 | M638: 1815 | N638: 30235.125 | O638: 1.3 | P638: =AND(A638>=(TODAY()-30),A638<TODAY()) -> FALSE | Q638: 3713.75 | R638: 19407.875 | S638: 7113.5
A639: 43918 | B639: 2639 | C639: 507.875 | D639: 570 | E639: 4274.375 | F639: 6207 | G639: 22.5 | H639: 6306.5 | I639: 2864 | J639: 2782.0741 | K639: 1326 | L639: 1113 | M639: 1820 | N639: 29054.25 | O639: 0.9 | P639: =AND(A639>=(TODAY()-30),A639<TODAY()) -> FALSE | Q639: 3716.875 | R639: 19674.375 | S639: 7041.0741
A640: 43919 | B640: 2603 | C640: 472.875 | D640: 550 | E640: 4293.375 | F640: 6125 | G640: 8.5 | H640: 6333.5 | I640: 3024.5 | J640: 2782.0741 | K640: 1321 | L640: 1095.5 | M640: 1811 | N640: 30662.75 | O640: 0.9 | P640: =AND(A640>=(TODAY()-30),A640<TODAY()) -> FALSE | Q640: 3625.875 | R640: 19784.875 | S640: 7009.5741
...

Sheet Park
A1: Date | B1: SS201_TxA (kWh) | C1: SS201_TxB (kWh) | D1: SS201_TxC (kWh) | E1: SS202_TxA (kWh) | F1: SS202_TxB (kWh) | G1: SS203_TxA (kWh) | H1: SS203_TxB (kWh) | I1: SS203_TxC (kWh) | J1: SS204_TxA (kWh) | K1: SS204_TxB (kWh) | L1: SS206_TxA (kWh) | M1: SS206_TxB (kWh) | N1: SS207_TxA (kWh) | O1: SS207_TxB (kWh) | P1: SS208_HV 11kV (kWh) | Q1: SS208_TxA (kWh) | R1: SS207_HV 11kV (kWh) | S1: PTI.SS200_TxA (kWh) | T1: PTI.SS211_TxA (kWh) | U1: GLA.SS210_TxA (kWh) | V1: SS209_TxA (kWh) | W1: SS209_TxB (kWh) | X1: Total Power Consumption of ThemePark (kWh) | Y1: Temperature | Z1: Attendance | AA1: Remarks | AB1: 30 Days
A2: 43282 | B2: 15717 | C2: 7629 | D2: 6337.75 | E2: 11216 | F2: 14220 | G2: 11678.75 | H2: 12096.5 | I2: 8390.5 | J2: 9170.25 | K2: 3441 | L2: 9415 | M2: 7973.5 | N2: 5042.125 | O2: 8632 | P2: 217.78125 | Q2: 3167.5 | R2: 529 | S2: 1505 | T2: 818.5 | U2: 4189.5 | X2: 141386.66 | Y2: 30.6 | AB2: =AND(A2>=(TODAY()-30),A2<TODAY()) -> FALSE
A3: 43283 | B3: 15428.5 | C3: 8176 | D3: 6246.75 | E3: 11269 | F3: 13561.5 | G3: 11047.25 | H3: 12447 | I3: 6456.25 | J3: 8979.75 | K3: 3379 | L3: 9002.5 | M3: 8011 | N3: 4952.125 | O3: 8609.5 | P3: 178.59375 | Q3: 2975.5 | R3: 472.125 | S3: 1483 | T3: 706 | U3: 4121 | X3: 137502.34 | Y3: 29 | AB3: =AND(A3>=(TODAY()-30),A3<TODAY()) -> FALSE
A4: 43284 | B4: 15678 | C4: 8775 | D4: 6098.75 | E4: 12106 | F4: 14064 | G4: 10860.25 | H4: 12330.25 | I4: 8204.75 | J4: 9309.25 | K4: 3382.75 | L4: 9733.5 | M4: 8155.5 | N4: 5237 | O4: 8510.5 | P4: 190.375 | Q4: 3369.5 | R4: 499.75 | S4: 1499.5 | T4: 727.5 | U4: 5212 | X4: 143944.12 | Y4: 29.154167 | AB4: =AND(A4>=(TODAY()-30),A4<TODAY()) -> FALSE
A5: 43285 | B5: 15300.5 | C5: 8265 | D5: 6114.5 | E5: 10599 | F5: 14164 | G5: 10707.25 | H5: 11659.75 | I5: 8565 | J5: 9300 | K5: 3251.5 | L5: 9871.5 | M5: 8257.5 | N5: 5073.625 | O5: 8685 | P5: 209.8125 | Q5: 3105 | R5: 514 | S5: 1510.5 | T5: 708 | U5: 5325.5 | X5: 141186.94 | Y5: 30.134375 | AB5: =AND(A5>=(TODAY()-30),A5<TODAY()) -> FALSE
A6: 43286 | B6: 15382.5 | C6: 8523 | D6: 6147.25 | E6: 11221 | F6: 13880.25 | G6: 9939.25 | H6: 11976 | I6: 8402.75 | J6: 9433.25 | K6: 3403.5 | L6: 10327.5 | M6: 8173.5 | N6: 5280.25 | O6: 8664 | P6: 203.40625 | Q6: 3416 | R6: 515.75 | S6: 1478.5 | T6: 648.5 | U6: 5217 | X6: 142233.16 | Y6: 28.803125 | AB6: =AND(A6>=(TODAY()-30),A6<TODAY()) -> FALSE
A7: 43287 | B7: 15493.5 | C7: 8322 | D7: 6268.5 | E7: 10906 | F7: 14124.75 | G7: 10677.75 | H7: 11788.5 | I7: 7130.75 | J7: 9316.375 | K7: 3392.75 | L7: 9895.5 | M7: 8280.5 | N7: 5261.125 | O7: 8683.5 | P7: 215.5625 | Q7: 3181 | R7: 586.125 | S7: 1572 | T7: 725.5 | U7: 5450.5 | X7: 141272.19 | Y7: 30 | AB7: =AND(A7>=(TODAY()-30),A7<TODAY()) -> FALSE
A8: 43288 | B8: 15164.5 | C8: 7368 | D8: 6243.25 | E8: 10786 | F8: 13346.75 | G8: 11218.75 | H8: 10755 | I8: 7443.5 | J8: 8956 | K8: 3370 | L8: 9648 | M8: 8075 | N8: 5163.375 | O8: 8567.5 | P8: 219.09375 | Q8: 3034.5 | R8: 546.875 | S8: 1550 | T8: 688 | U8: 5014 | X8: 137158.09 | Y8: 29.1 | AB8: =AND(A8>=(TODAY()-30),A8<TODAY()) -> FALSE
A9: 43289 | B9: 15477.5 | C9: 7231 | D9: 6245.25 | E9: 10588 | F9: 13278.75 | G9: 12288.75 | H9: 10855 | I9: 5491.75 | J9: 8856 | K9: 3372.75 | L9: 9653.5 | M9: 7791.5 | N9: 5202.625 | O9: 8567.5 | P9: 233 | Q9: 3080.5 | R9: 586.25 | S9: 1506.5 | T9: 699.5 | U9: 4539.5 | X9: 135545.12 | Y9: 28.744792 | AB9: =AND(A9>=(TODAY()-30),A9<TODAY()) -> FALSE
A10: 43290 | B10: 15727 | C10: 8249 | D10: 6231.75 | E10: 10639 | F10: 13209.5 | G10: 10032.5 | H10: 12478.75 | I10: 7201.25 | J10: 8936.125 | K10: 3370 | L10: 9870 | M10: 8433 | N10: 5069 | O10: 8393 | P10: 229.875 | Q10: 3059.5 | R10: 570.125 | S10: 1437 | T10: 694.5 | U10: 5394 | X10: 139224.88 | Y10: 29.107292 | AB10: =AND(A10>=(TODAY()-30),A10<TODAY()) -> FALSE
A11: 43291 | B11: 15488 | C11: 8389 | D11: 6170.5 | E11: 10634 | F11: 13654 | G11: 10158.5 | H11: 12007.75 | I11: 7218.25 | J11: 9070.5 | K11: 3295.5 | L11: 10028 | M11: 8373 | N11: 5126.5 | O11: 8662 | P11: 226.875 | Q11: 3163 | R11: 570.375 | S11: 1421 | T11: 665.5 | U11: 5477 | X11: 139799.25 | Y11: 29.282474 | AB11: =AND(A11>=(TODAY()-30),A11<TODAY()) -> FALSE
A12: 43292 | B12: 15444 | C12: 8461 | D12: 6207 | E12: 10555 | F12: 13684.25 | G12: 9769.5 | H12: 13158.5 | I12: 6961 | J12: 9501.25 | K12: 3266 | L12: 10200 | M12: 8335 | N12: 5134.375 | O12: 8585 | P12: 224.03125 | Q12: 3211 | R12: 483 | S12: 1449 | T12: 731 | U12: 5456 | X12: 140815.91 | Y12: 29.856701 | AB12: =AND(A12>=(TODAY()-30),A12<TODAY()) -> FALSE
A13: 43293 | B13: 15394.5 | C13: 8393 | D13: 6211.75 | E13: 10593 | F13: 13891 | G13: 11677.25 | H13: 10125.25 | I13: 7443.25 | J13: 9504.125 | K13: 3305.25 | L13: 10328.5 | M13: 8407.5 | N13: 5107.75 | O13: 8799 | P13: 201.15625 | Q13: 3172 | R13: 592.625 | S13: 1499.5 | T13: 681 | U13: 5362 | X13: 140689.41 | Y13: 30.2 | AB13: =AND(A13>=(TODAY()-30),A13<TODAY()) -> FALSE
... A338: 43618 | B338: 13407 | C338: 9704 | D338: 5661.5 | E338: 10267 | F338: 9243.5 | G338: 12333 | H338: 9652.5 | I338: 7476.5 | J338: 8873.25 | K338: 3681.5 | L338: 8716.625 | M338: 6554 | N338: 5006 | O338: 9070.9688 | P338: 175.75 | Q338: 2923 | R338: 431.375 | S338: 1311.5 | T338: 747.5 | U338: 4493 | X338: 129729.47 | Y338: 25.9 | AB338: =AND(A338>=(TODAY()-30),A338<TODAY()) -> FALSE
A339: 43619 | B339: 14876 | C339: 9569 | D339: 5638 | E339: 10002.25 | F339: 9460 | G339: 11058 | H339: 9977.5 | I339: 7836 | J339: 9339.25 | K339: 3514.75 | L339: 9550.75 | M339: 7418 | N339: 4783.5 | O339: 8947.3125 | P339: 196.4375 | Q339: 2815 | R339: 408.25 | S339: 1352.5 | T339: 736 | U339: 5234 | X339: 132712.5 | Y339: Data Loss | AB339: =AND(A339>=(TODAY()-30),A339<TODAY()) -> FALSE
A340: 43620 | B340: 14531 | C340: 10207.75 | D340: 5546.5 | E340: 10464.25 | F340: 9926.5 | G340: 11690.5 | H340: 10209.5 | I340: 6934.5 | J340: 9446.75 | K340: 3820.5 | L340: 9968.5 | M340: 7401 | N340: 5010 | O340: 9179.5312 | P340: 178.5 | Q340: 2822.5 | R340: 339.125 | S340: 1376 | T340: 688 | U340: 5223 | X340: 134963.91 | Y340: Data Loss | AB340: =AND(A340>=(TODAY()-30),A340<TODAY()) -> FALSE
A341: 43621 | B341: 15112 | C341: 9873.25 | D341: 5761 | E341: 10356 | F341: 11914.5 | G341: 11583 | H341: 11068.5 | I341: 6942.5 | J341: 9586.5 | K341: 3299.25 | L341: 10009.625 | M341: 7587 | N341: 5196.75 | O341: 9202.9062 | P341: 191.8125 | Q341: 2877 | R341: 442.5 | S341: 1540.5 | T341: 773.5 | U341: 5669 | X341: 138987.09 | Y341: 29.420619 | AB341: =AND(A341>=(TODAY()-30),A341<TODAY()) -> FALSE
A342: 43622 | B342: 15892 | C342: 9896.5 | D342: 5609.5 | E342: 10557.25 | F342: 13415 | G342: 11941.5 | H342: 10360 | I342: 8021 | J342: 9755.5 | K342: 3805.75 | L342: 10315.875 | M342: 7744 | N342: 5227.75 | O342: 9487.5938 | P342: 213.5 | Q342: 3066.5 | R342: 534.75 | S342: 1567 | T342: 770.5 | U342: 5617 | X342: 143798.47 | Y342: 30.430928 | AB342: =AND(A342>=(TODAY()-30),A342<TODAY()) -> FALSE
A343: 43623 | B343: 15572 | C343: 9874.25 | D343: 5896 | E343: 10776 | F343: 13320.5 | G343: 12601 | H343: 11279.5 | I343: 7970 | J343: 9608 | K343: 3450 | L343: 9672.125 | M343: 7735 | N343: 5408.75 | O343: 9578.4688 | P343: 244.3125 | Q343: 3151 | R343: 612.25 | S343: 1590 | T343: 832 | U343: 4947 | X343: 144118.16 | Y343: 30.8 | AB343: =AND(A343>=(TODAY()-30),A343<TODAY()) -> FALSE
A344: 43624 | B344: 15958 | C344: 8956.25 | D344: 6067 | E344: 10739.5 | F344: 13602 | G344: 11973 | H344: 11186.5 | I344: 9049.5 | J344: 9419.25 | K344: 3377 | L344: 9247.875 | M344: 7900 | N344: 5426.25 | O344: 9574.4375 | P344: 247.8125 | Q344: 3194 | R344: 601.75 | S344: 1571.5 | T344: 795 | U344: 5274 | X344: 144160.62 | Y344: 31.6 | AB344: =AND(A344>=(TODAY()-30),A344<TODAY()) -> FALSE
A345: 43625 | B345: 14859 | C345: 9269.5 | D345: 5868 | E345: 10416.25 | F345: 13486.5 | G345: 10677.5 | H345: 11786 | I345: 8300 | J345: 9290.25 | K345: 3335 | L345: 8774 | M345: 7456 | N345: 5382 | O345: 9297.75 | P345: 210 | Q345: 3184.5 | R345: 480.375 | S345: 1627 | T345: 779.5 | U345: 4913 | X345: 139392.12 | Y345: 31.8 | AB345: =AND(A345>=(TODAY()-30),A345<TODAY()) -> FALSE
A346: 43626 | B346: 15216 | C346: 9559.25 | D346: 5759 | E346: 10094.5 | F346: 12716.5 | G346: 10517 | H346: 11328 | I346: 7353 | J346: 9470 | K346: 3218.25 | L346: 9782 | M346: 7819 | N346: 5129.25 | O346: 9124.375 | P346: 178.625 | Q346: 2886 | R346: 432 | S346: 1535.5 | T346: 792.5 | U346: 5449 | X346: 138359.75 | Y346: 29.2 | AB346: =AND(A346>=(TODAY()-30),A346<TODAY()) -> FALSE
A347: 43627 | B347: 14218 | C347: 10615.5 | D347: 5289 | E347: 10289.75 | F347: 11610.5 | G347: 11458.5 | H347: 9428.5 | I347: 7504 | J347: 9191 | K347: 3497 | L347: 10433.125 | M347: 7488 | N347: 5032.25 | O347: 9109.75 | P347: 159.5 | Q347: 2997 | R347: 368.75 | S347: 1445 | T347: 832.5 | U347: 5243 | X347: 136210.62 | Y347: 27.006186 | AB347: =AND(A347>=(TODAY()-30),A347<TODAY()) -> FALSE
A348: 43628 | B348: 14751 | C348: 9739.25 | D348: 5178.5 | E348: 9941.5 | F348: 11656.5 | G348: 7931 | H348: 12037.5 | I348: 7948 | J348: 9526.5 | K348: 3291.5 | L348: 10058.25 | M348: 7175 | N348: 4989.25 | O348: 9046.75 | P348: 176.0625 | Q348: 2945.5 | R348: 402.875 | S348: 1426.5 | T348: 775 | U348: 5251 | X348: 134247.44 | Y348: 27.55567 | AB348: =AND(A348>=(TODAY()-30),A348<TODAY()) -> FALSE
A349: 43629 | B349: 14794 | C349: 10012.5 | D349: 5130.5 | E349: 10443.75 | F349: 10952 | G349: 7861 | H349: 11154 | I349: 8402 | J349: 9556.25 | K349: 3596.5 | L349: 9819.875 | M349: 7114 | N349: 4919.5 | O349: 9108.5 | P349: 130.625 | Q349: 3065.5 | R349: 318 | S349: 1375.5 | T349: 710.5 | U349: 5045 | X349: 133509.5 | Y349: 27.330928 | AB349: =AND(A349>=(TODAY()-30),A349<TODAY()) -> FALSE
A350: 43630 | B350: 14734 | C350: 10145.5 | D350: 5407 | E350: 10928.25 | F350: 12034.5 | G350: 7881 | H350: 11930.5 | I350: 8759.5 | J350: 9363.5 | K350: 3252 | L350: 10070.25 | M350: 7623 | N350: 5159.25 | O350: 8917.9375 | P350: 203.6875 | Q350: 3103 | R350: 497.125 | S350: 1339.5 | T350: 866.5 | U350: 5323 | X350: 137539 | Y350: 29.2 | AB350: =AND(A350>=(TODAY()-30),A350<TODAY()) -> FALSE
A351: 43631 | B351: 15082 | C351: 9186.25 | D351: 6016 | E351: 10605 | F351: 12313 | G351: 8500 | H351: 10967 | I351: 10466.5 | J351: 9504.5 | K351: 3405.75 | L351: 9948.25 | M351: 7487 | N351: 5203.75 | O351: 9250 | P351: 209.8125 | Q351: 3183.5 | R351: 515.5 | S351: 1358 | T351: 1069.5 | U351: 5108 | X351: 139379.31 | Y351: 30.2 | AB351: =AND(A351>=(TODAY()-30),A351<TODAY()) -> FALSE
A352: 43632 | B352: 15123.122 | C352: 9111.25 | D352: 5980 | E352: 10759.75 | F352: 12336 | G352: 8274.5 | H352: 12758 | I352: 8668 | J352: 9436.5 | K352: 3499.75 | L352: 9531.75 | M352: 6997 | N352: 5120.5 | O352: 9142.125 | P352: 188.125 | Q352: 3266 | R352: 460.25 | S352: 1354.5 | T352: 1002.5 | U352: 4632 | X352: 137641.62 | Y352: 30.1 | AB352: =AND(A352>=(TODAY()-30),A352<TODAY()) -> FALSE
... A397: 43677 | B397: 11971.188 | C397: 8540.5 | D397: 5155 | E397: 8108.5 | F397: 7017 | G397: 7310 | H397: 7871.5 | I397: 3087 | J397: 8988.5 | K397: 2573 | L397: 7287.75 | M397: 6400 | N397: 3759 | O397: 6139.3125 | P397: 50.5625 | Q397: 2057 | R397: 160.125 | S397: 1116.5 | T397: 578.5 | U397: 3099 | X397: 101269.94 | Y397: 26.6 | AB397: =AND(A397>=(TODAY()-30),A397<TODAY()) -> FALSE
A398: 43678 | B398: 14362.312 | C398: 9398.5 | D398: 5717.5 | E398: 10185.75 | F398: 8351 | G398: 9133 | H398: 11472 | I398: 4881.5 | J398: 10361.5 | K398: 3748.25 | L398: 10229.25 | M398: 7070 | N398: 3872 | O398: 8535 | P398: 42.9375 | Q398: 2632 | R398: 163.5 | S398: 1157 | T398: 627 | U398: 4937 | X398: 126877 | Y398: 26.5 | Z398: 26 | AA398: =IF(Z398=0,"CLOSE","OPEN") -> OPEN | AB398: =AND(A398>=(TODAY()-30),A398<TODAY()) -> FALSE
A399: 43679 | B399: 15029.062 | C399: 10275.25 | D399: 5865 | E399: 9695.5 | F399: 9830.5 | G399: 12304 | H399: 12326 | I399: 7376.5 | J399: 10993 | K399: 3806.5 | L399: 10043.5 | M399: 7636 | N399: 5114.5 | O399: 8923.9375 | P399: 226.5 | Q399: 3131.5 | R399: 535 | S399: 1231 | T399: 705 | U399: 5476 | X399: 140524.25 | Y399: 27.656701 | Z399: 26 | AA399: =IF(Z399=0,"CLOSE","OPEN") -> OPEN | AB399: =AND(A399>=(TODAY()-30),A399<TODAY()) -> FALSE
A400: 43680 | B400: 13607.875 | C400: 10298.5 | D400: 5832 | E400: 10388.25 | F400: 9560.5 | G400: 12178 | H400: 13629 | I400: 6686 | J400: 10698.5 | K400: 3723.5 | L400: 9997.875 | M400: 7138 | N400: 5187 | O400: 8808.25 | P400: 228.875 | Q400: 3176.5 | R400: 536.875 | S400: 1198.5 | T400: 692.5 | U400: 5162 | X400: 138728.5 | Y400: 27.374227 | Z400: 26 | AA400: =IF(Z400=0,"CLOSE","OPEN") -> OPEN | AB400: =AND(A400>=(TODAY()-30),A400<TODAY()) -> FALSE
A401: 43681 | B401: 14705.938 | C401: 9021 | D401: 5904 | E401: 10280 | F401: 9800.5 | G401: 12103 | H401: 13347.5 | I401: 7536 | J401: 9763 | K401: 3872.25 | L401: 9084 | M401: 7086 | N401: 5102.5 | O401: 8677.875 | P401: 221.625 | Q401: 3096 | R401: 518.125 | S401: 1213.5 | T401: 713 | U401: 4669 | X401: 136714.81 | Y401: 29.002062 | Z401: 26 | AA401: =IF(Z401=0,"CLOSE","OPEN") -> OPEN | AB401: =AND(A401>=(TODAY()-30),A401<TODAY()) -> FALSE
A402: 43682 | B402: 14268.625 | C402: 10129 | D402: 5754.5 | E402: 10063.25 | F402: 9935 | G402: 13934 | H402: 12974 | I402: 3931 | J402: 10271 | K402: 3310.25 | L402: 8636.375 | M402: 7600 | N402: 4817 | O402: 7368.25 | P402: 153.125 | Q402: 2903.5 | R402: 165.25 | S402: 1279.5 | T402: 603.5 | U402: 5207 | X402: 133304.12 | Y402: 30.2 | Z402: 15 | AA402: =IF(Z402=0,"CLOSE","OPEN") -> OPEN | AB402: =AND(A402>=(TODAY()-30),A402<TODAY()) -> FALSE
A403: 43683 | B403: 15132.438 | C403: 10157.25 | D403: 5847 | E403: 10302.5 | F403: 10016 | G403: 13355 | H403: 14274.5 | I403: 5391.5 | J403: 11233 | K403: 3185.5 | L403: 10406.75 | M403: 7681 | N403: 5347 | O403: 8583.5 | P403: 219.625 | Q403: 3145 | R403: 557.125 | S403: 1304.5 | T403: 725.5 | U403: 5474 | X403: 142338.69 | Y403: 30 | Z403: 22 | AA403: =IF(Z403=0,"CLOSE","OPEN") -> OPEN | AB403: =AND(A403>=(TODAY()-30),A403<TODAY()) -> FALSE
A404: 43684 | B404: 14674.875 | C404: 10515.5 | D404: 5849 | E404: 10469.75 | F404: 10016 | G404: 13859 | H404: 13383 | I404: 5601.5 | J404: 11289 | K404: 3339.25 | L404: 10117.5 | M404: 7962 | N404: 5330.75 | O404: 8792.875 | P404: 213.8125 | Q404: 3159.5 | R404: 539.875 | S404: 1276.5 | T404: 688.5 | U404: 5649 | X404: 142727.19 | Y404: 30.6 | Z404: 22 | AA404: =IF(Z404=0,"CLOSE","OPEN") -> OPEN | AB404: =AND(A404>=(TODAY()-30),A404<TODAY()) -> FALSE
A405: 43685 | B405: 15495.938 | C405: 9958.75 | D405: 5859.5 | E405: 10520.25 | F405: 9654.5 | G405: 13641 | H405: 13451.5 | I405: 5589.5 | J405: 11505.5 | K405: 3404 | L405: 10909.625 | M405: 8107 | N405: 5347.75 | O405: 8791 | P405: 208.9375 | Q405: 3198.5 | R405: 540.125 | S405: 1353 | T405: 727.5 | U405: 5643 | X405: 143906.88 | Y405: 31.3 | Z405: 22 | AA405: =IF(Z405=0,"CLOSE","OPEN") -> OPEN | AB405: =AND(A405>=(TODAY()-30),A405<TODAY()) -> FALSE
A406: 43686 | B406: 15187.5 | C406: 10224.75 | D406: 5871 | E406: 10545.25 | F406: 10701 | G406: 10135 | H406: 15004.5 | I406: 6714.5 | J406: 11712 | K406: 3228.75 | L406: 10599.875 | M406: 8250 | N406: 5330 | O406: 8917.375 | P406: 208.5 | Q406: 3334 | R406: 477.125 | S406: 1464 | T406: 767.5 | U406: 5670 | X406: 144342.62 | Y406: 32.4 | Z406: 26 | AA406: =IF(Z406=0,"CLOSE","OPEN") -> OPEN | AB406: =AND(A406>=(TODAY()-30),A406<TODAY()) -> FALSE
A407: 43687 | B407: 14411.375 | C407: 9707.5 | D407: 5925 | E407: 10441.25 | F407: 10591.5 | G407: 11061 | H407: 13495.5 | I407: 6395.5 | J407: 11169 | K407: 3206 | L407: 9256.375 | M407: 7810 | N407: 5312.75 | O407: 8735 | P407: 197 | Q407: 3348 | R407: 491.625 | S407: 1577 | T407: 812 | U407: 5117 | X407: 139060.38 | Y407: 32 | Z407: 26 | AA407: =IF(Z407=0,"CLOSE","OPEN") -> OPEN | AB407: =AND(A407>=(TODAY()-30),A407<TODAY()) -> FALSE
A408: 43688 | B408: 14992.375 | C408: 9019.5 | D408: 5879.5 | E408: 10351.5 | F408: 10539.5 | G408: 10177 | H408: 13183 | I408: 7013 | J408: 10275 | K408: 3205.25 | L408: 9047.875 | M408: 7582 | N408: 5303.25 | O408: 8764.875 | P408: 209.625 | Q408: 3182.5 | R408: 507.25 | S408: 1681.5 | T408: 835.5 | U408: 4605 | X408: 136355 | Y408: 32.3 | Z408: 26 | AA408: =IF(Z408=0,"CLOSE","OPEN") -> OPEN | AB408: =AND(A408>=(TODAY()-30),A408<TODAY()) -> FALSE
...

Sheet Meter Base
A1: Substation | B1: Supply Transformer | C1: Meter No | G1: Meter Description | I1: Parent | J1: MCCB No | K1: Service Area
A2: 631 Substation 201 | B2: T201-A | C2: Group | D2: B | E2: 9132381 | F2: 9110240(FiT) 9115380(FiT) 10214781(FiT) | G2: CLP KWH Meter | H2: ID
D3: SS201_Tx_A | G3: PMCS "A" Meter | H3: A000 | I3: 9046928
D4: (Solar Panel) | E4: ="SS201_" & J4 -> SS201_A1 | G4: PMCS "B" Meter | I4: SS201_Tx_A | J4: A1 | K4: 602 Wardrobe/Adminstration Normal Power
D5: (Solar Panel) | E5: ="SS201_" & J5 -> SS201_A2 | G5: PMCS "B" Meter | I5: SS201_Tx_A | J5: A2 | K5: 302 Tomorrow Terrace Restaurant Normal Power
E6: ="SS201_" & J6 -> SS201_A3 | G6: PMCS "B" Meter | I6: SS201_Tx_A | J6: A3 | K6: 203 Main Street Train Station
E7: ="SS201_" & J7 -> SS201_A4 | G7: PMCS "B" Meter | I7: SS201_Tx_A | J7: A4 | K7: 208 Main Street Corner Café, Baby Care Centre, First Aid, Crystal Arts Normal Power
E8: ="SS201_" & J8 -> SS201_A5 | G8: PMCS "B" Meter | I8: SS201_Tx_A | J8: A5 | K8: 624 Cleansing Water Tank Pumps Normal Power
E9: ="SS201_" & J9 -> SS201_A6 | G9: PMCS "B" Meter | I9: SS201_Tx_A | J9: A6 | K9: 316 Air Compressor Plant Normal Power
E10: ="SS201_" & J10 -> SS201_A7 | G10: PMCS "B" Meter | I10: SS201_Tx_A | J10: A7 | K10: Spare
E11: ="SS201_" & J11 -> SS201_A8 | G11: PMCS "B" Meter | I11: SS201_Tx_A | J11: A8 | K11: Spare
E12: SS201_A14 | J12: A14 | K12: Capacitor Bank
E13: ="SS201_" & J13 -> SS201_ATS201-A (A9) | G13: PMCS "B" Meter | I13: SS201_Tx_A | J13: ATS201-A (A9) | K13: Auto Change Over
F14: ="SS201_" & J14 -> SS201_EA1 | G14: PMCS "B" Meter | I14: SS201_ATS201-A | J14: EA1 | K14: 602 Wardrobe/Adminstration Essential Power
F15: ="SS201_" & J15 -> SS201_EA2 | G15: PMCS "B" Meter | I15: SS201_ATS201-A | J15: EA2 | K15: 302 Tomorrow Terrace Restaurant Essential Power
F16: ="SS201_" & J16 -> SS201_EA3 | G16: PMCS "B" Meter | I16: SS201_ATS201-A | J16: EA3 | K16: 203 Main Street Train Station Essential Power
F17: ="SS201_" & J17 -> SS201_EA4 | G17: PMCS "B" Meter | I17: SS201_ATS201-A | J17: EA4 | K17: 208 Main Street Corner Café, Baby Care Centre, First Aid, Crystal Arts Essentail Power
F18: ="SS201_" & J18 -> SS201_EA5 | G18: PMCS "B" Meter | I18: SS201_ATS201-A | J18: EA5 | K18: 624 Flushing Water Tank Pumps Essential Power
B19: T201-B | C19: Group | D19: C | E19: 9132428 | F19: 9110234(FiT) | G19: CLP KWH Meter
D20: SS201_Tx_B | G20: PMCS "A" Meter | I20: 9045183
D21: (Solar Panel) | E21: ="SS201_" & J21 -> SS201_B1 | G21: PMCS "B" Meter | I21: SS201_Tx_B | J21: B1 | K21: 304 Buzz Lightyear Astro Blasters Normal Power
E22: ="SS201_" & J22 -> SS201_B2 | G22: PMCS "B" Meter | I22: SS201_Tx_B | J22: B2 | K22: 204 Opera House Normal Power
E23: ="SS201_" & J23 -> SS201_B3 | G23: PMCS "B" Meter | I23: SS201_Tx_B | J23: B3 | K23: 206 Town Square Photo, Midtown Jewelry, Market House Bakery Normal Power
E24: ="SS201_" & J24 -> SS201_B4 | G24: PMCS "B" Meter | I24: SS201_Tx_B | J24: B4 | K24: DB-Contianer Location C"
E25: ="SS201_" & J25 -> SS201_ATS201-B (B5) | G25: PMCS "B" Meter | I25: SS201_Tx_B | J25: ATS201-B (B5) | K25: Auto change Over
E26: ="SS201_" & J26 -> SS201_B6 | G26: PMCS "B" Meter | I26: SS201_Tx_B | J26: B6 | K26: 631 Exterior LTG. MCB1 Normal Power
E27: ="SS201_" & J27 -> SS201_B8 | G27: PMCS "B" Meter | I27: SS201_Tx_B | J27: B8 | K27: 316 Area Development Air Compressor Plant & Water Filtration Plant
E28: SS201_B11 | K28: Capacitor Bank
E29: ="SS201_" & J29 -> SS201_B13 | G29: PMCS "B" Meter | I29: SS201_Tx_B | J29: B13 | K29: 645-MSB Wardrobe/Adminstration Normal Power
D30: No PMb | E30: ="SS201_" & J30 -> SS201_B14 | J30: B14 | K30: SPARE
F31: ="SS201_" & J31 -> SS201_EB1 | G31: PMCS "B" Meter | I31: SS201_ATS201-B | J31: EB1 | K31: 304 Buzz Lightyear Astro Blasters Essential Power
F32: ="SS201_" & J32 -> SS201_EB2 | G32: PMCS "B" Meter | I32: SS201_ATS201-B | J32: EB2 | K32: 204 Opera House Essential Power
F33: ="SS201_" & J33 -> SS201_EB3 | G33: PMCS "B" Meter | I33: SS201_ATS201-B | J33: EB3 | K33: 206 Town Square Photo, Midtown Jewelry, Market House Bakery Essential Power
D34: No PMb | F34: ="SS201_" & J34 -> SS201_EB4 | G34: PMCS "B" Meter | I34: SS201_ATS201-B | J34: EB4 | K34: 631 AUX. Load EMCB1 Essential
F35: ="SS201_" & J35 -> SS201_EB5 | G35: PMCS "B" Meter | I35: SS201_ATS201-B | J35: EB5 | K35: 645-EMSB1A Wardrobe/Adminstration Essential Power
F36: ="SS201_" & J36 -> SS201_EB6 | G36: PMCS "B" Meter | I36: SS201_ATS201-B | J36: EB6 | K36: GLA Service Tunnel Sump
B37: T201-C | C37: Group | D37: AT | E37: 9132711 | F37: 7600760(FiT) | G37: CLP KWH Meter
D38: SS201_Tx_C | G38: PMCS "A" Meter | I38: 9101575
D39: (Solar Panel) | E39: ="SS201_" & J39 -> SS201_C1 | G39: PMCS "B" Meter | I39: SS201_Tx_C | J39: C1 | K39: 310S-MSB1 IRONMAN EXPERIENCE RIDE Normal Power
E40: ="SS201_" & J40 -> SS201_C2 | G40: PMCS "B" Meter | I40: SS201_Tx_C | J40: C2 | K40: Spare
...
